Workbook

Sheet Dashboard
A1: MASTER SUMMARY DASHBOARD
A2: Sample operations overview | Update Activity Data to refresh formula-based KPIs
A4: Total Activities | C4: Completed | E4: Open Activities
A5: =COUNTA('Activity Data'!A2:A121) -> 120 | C5: =COUNTIF('Activity Data'!H2:H121,"Completed") -> 80 | E5: =COUNTIF('Activity Data'!H2:H121,"Pending")+COUNTIF('Activity Data'!H2:H121,"In Progress") -> 31
A7: Completion Rate | C7: TAT Met Rate | E7: Checklist Compliance
A8: =IFERROR(B5/B4,0) -> 0 | C8: =IFERROR(COUNTIF('Activity Data'!J2:J121,"Yes")/COUNTIF('Activity Data'!J2:J121,"<>N/A"),0) -> 0.5045045 | E8: =IFERROR(COUNTIF('Activity Data'!I2:I121,"Yes")/(COUNTIF('Activity Data'!I2:I121,"Yes")+COUNTIF('Activity Data'!I2:I121,"No")),0) -> 0.85585586
A11: Activities by Status | D11: Activities by Region
A12: Status | B12: Count | D12: Region | E12: Count
A13: Completed | B13: =COUNTIF('Activity Data'!H:H,A13) -> 80 | D13: North | E13: =COUNTIF('Activity Data'!C:C,D13) -> 24
A14: Pending | B14: =COUNTIF('Activity Data'!H:H,A14) -> 7 | D14: South | E14: =COUNTIF('Activity Data'!C:C,D14) -> 31
A15: In Progress | B15: =COUNTIF('Activity Data'!H:H,A15) -> 24 | D15: East | E15: =COUNTIF('Activity Data'!C:C,D15) -> 31
A16: Cancelled | B16: =COUNTIF('Activity Data'!H:H,A16) -> 9 | D16: West | E16: =COUNTIF('Activity Data'!C:C,D16) -> 34

Sheet Activity Data
A1: Activity ID | B1: Date | C1: Region | D1: Activity Type | E1: Assigned To | F1: TAT Target (hrs) | G1: Actual TAT (hrs) | H1: Status | I1: Checklist Complete | J1: TAT Met
A2: ACT-023 | B2: 46235 | C2: South | D2: Installation | E2: Rohan | F2: 24 | G2: 25 | H2: Completed | I2: Yes | J2: No
A3: ACT-097 | B3: 46235 | C3: West | D3: Installation | E3: Sara | F3: 24 | G3: 26 | H3: Pending | I3: Yes | J3: No
A4: ACT-098 | B4: 46235 | C4: West | D4: Inspection | E4: Ishaan | F4: 4 | G4: 3 | H4: Completed | I4: Yes | J4: Yes
A5: ACT-022 | B5: 46236 | C5: West | D5: Inspection | E5: Aarav | F5: 8 | G5: 9 | H5: In Progress | I5: Yes | J5: No
A6: ACT-061 | B6: 46236 | C6: North | D6: Installation | E6: Rohan | F6: 24 | G6: 35 | H6: Completed | I6: Yes | J6: No
A7: ACT-037 | B7: 46237 | C7: West | D7: Inspection | E7: Kabir | F7: 24 | G7: 31 | H7: Completed | I7: Yes | J7: No
A8: ACT-077 | B8: 46238 | C8: South | D8: Inspection | E8: Diya | F8: 12 | G8: 13 | H8: Completed | I8: Yes | J8: No
A9: ACT-065 | B9: 46238 | C9: East | D9: Maintenance | E9: Aarav | F9: 4 | G9: 2 | H9: Completed | I9: Yes | J9: Yes
A10: ACT-068 | B10: 46239 | C10: West | D10: Customer Visit | E10: Ishaan | F10: 8 | G10: 11 | H10: Completed | I10: No | J10: No
A11: ACT-111 | B11: 46239 | C11: South | D11: Installation | E11: Meera | F11: 12 | G11: 11 | H11: Completed | I11: No | J11: Yes
A12: ACT-076 | B12: 46239 | C12: South | D12: Installation | E12: Kabir | F12: 24 | G12: 20 | H12: Completed | I12: Yes | J12: Yes
A13: ACT-026 | B13: 46240 | C13: South | D13: Installation | E13: Meera | F13: 4 | H13: Cancelled | I13: N/A | J13: N/A
A14: ACT-071 | B14: 46240 | C14: East | D14: Installation | E14: Ishaan | F14: 4 | G14: 5 | H14: Completed | I14: Yes | J14: No
A15: ACT-004 | B15: 46240 | C15: North | D15: Customer Visit | E15: Anaya | F15: 4 | G15: 6 | H15: Pending | I15: Yes | J15: No
A16: ACT-017 | B16: 46241 | C16: North | D16: Customer Visit | E16: Anaya | F16: 48 | H16: Cancelled | I16: N/A | J16: N/A
A17: ACT-029 | B17: 46242 | C17: South | D17: Installation | E17: Diya | F17: 48 | G17: 34 | H17: Completed | I17: Yes | J17: Yes
A18: ACT-007 | B18: 46242 | C18: West | D18: Installation | E18: Aarav | F18: 24 | G18: 25 | H18: Completed | I18: Yes | J18: No
A19: ACT-096 | B19: 46242 | C19: East | D19: Maintenance | E19: Anaya | F19: 12 | G19: 17 | H19: In Progress | I19: Yes | J19: No
A20: ACT-081 | B20: 46243 | C20: South | D20: Customer Visit | E20: Ishaan | F20: 8 | H20: Cancelled | I20: N/A | J20: N/A
A21: ACT-036 | B21: 46244 | C21: West | D21: Customer Visit | E21: Aarav | F21: 48 | G21: 30 | H21: Completed | I21: No | J21: Yes
A22: ACT-093 | B22: 46246 | C22: South | D22: Maintenance | E22: Aarav | F22: 4 | G22: 3 | H22: Completed | I22: Yes | J22: Yes
A23: ACT-083 | B23: 46246 | C23: East | D23: Maintenance | E23: Diya | F23: 8 | G23: 10 | H23: In Progress | I23: Yes | J23: No
A24: ACT-010 | B24: 46247 | C24: South | D24: Inspection | E24: Diya | F24: 48 | G24: 48 | H24: Completed | I24: No | J24: Yes
A25: ACT-012 | B25: 46248 | C25: East | D25: Maintenance | E25: Anaya | F25: 4 | G25: 3 | H25: Completed | I25: Yes | J25: Yes
A26: ACT-090 | B26: 46249 | C26: West | D26: Installation | E26: Aarav | F26: 8 | G26: 5 | H26: Completed | I26: Yes | J26: Yes
A27: ACT-045 | B27: 46250 | C27: West | D27: Inspection | E27: Rohan | F27: 48 | G27: 52 | H27: Completed | I27: Yes | J27: No
A28: ACT-088 | B28: 46251 | C28: East | D28: Customer Visit | E28: Ishaan | F28: 12 | G28: 16 | H28: Completed | I28: Yes | J28: No
A29: ACT-006 | B29: 46251 | C29: East | D29: Inspection | E29: Kabir | F29: 12 | G29: 10 | H29: Completed | I29: Yes | J29: Yes
A30: ACT-053 | B30: 46252 | C30: North | D30: Maintenance | E30: Aarav | F30: 24 | G30: 19 | H30: Pending | I30: No | J30: Yes
A31: ACT-100 | B31: 46252 | C31: West | D31: Installation | E31: Ishaan | F31: 4 | G31: 3 | H31: Completed | I31: Yes | J31: Yes
A32: ACT-041 | B32: 46252 | C32: West | D32: Inspection | E32: Anaya | F32: 8 | G32: 5 | H32: Completed | I32: Yes | J32: Yes
... A91: ACT-034 | B91: 46281 | C91: East | D91: Installation | E91: Kabir | F91: 24 | G91: 12 | H91: In Progress | I91: Yes | J91: Yes
A92: ACT-001 | B92: 46282 | C92: North | D92: Maintenance | E92: Meera | F92: 48 | H92: Cancelled | I92: N/A | J92: N/A
A93: ACT-074 | B93: 46283 | C93: North | D93: Inspection | E93: Anaya | F93: 12 | G93: 17 | H93: Completed | I93: Yes | J93: No
A94: ACT-003 | B94: 46283 | C94: West | D94: Inspection | E94: Aarav | F94: 12 | G94: 14 | H94: Completed | I94: Yes | J94: No
A95: ACT-086 | B95: 46284 | C95: East | D95: Installation | E95: Diya | F95: 24 | H95: Cancelled | I95: N/A | J95: N/A
A96: ACT-030 | B96: 46284 | C96: South | D96: Installation | E96: Kabir | F96: 4 | G96: 5 | H96: Completed | I96: Yes | J96: No
A97: ACT-091 | B97: 46285 | C97: West | D97: Installation | E97: Sara | F97: 48 | G97: 41 | H97: In Progress | I97: Yes | J97: Yes
A98: ACT-047 | B98: 46285 | C98: East | D98: Maintenance | E98: Kabir | F98: 12 | G98: 10 | H98: Completed | I98: Yes | J98: Yes
...

Sheet FMS Summary
A1: FMS DASHBOARD – FIELD ACTIVITY TRACKER
A2: Field Management System (FMS) summary based on the sample activity log.
A4: Metric | B4: Value
A5: Total field activities | B5: =COUNTA('Activity Data'!A2:A121) -> 120
A6: Completed | B6: =COUNTIF('Activity Data'!H2:H121,"Completed") -> 80
A7: Pending | B7: =COUNTIF('Activity Data'!H2:H121,"Pending") -> 7
A8: In Progress | B8: =COUNTIF('Activity Data'!H2:H121,"In Progress") -> 24
A9: Activities meeting TAT | B9: =COUNTIF('Activity Data'!J2:J121,"Yes") -> 56
A10: Activities exceeding TAT | B10: =COUNTIF('Activity Data'!J2:J121,"No") -> 55
A11: Checklist marked complete | B11: =COUNTIF('Activity Data'!I2:I121,"Yes") -> 95

Sheet Checklist Summary
A1: CHECKLIST COMPLIANCE DASHBOARD
A3: Checklist Status | B3: Count
A4: Complete | B4: =COUNTIF('Activity Data'!I2:I121,"Yes") -> 95
A5: Incomplete | B5: =COUNTIF('Activity Data'!I2:I121,"No") -> 16
A6: Not Applicable | B6: =COUNTIF('Activity Data'!I2:I121,"N/A") -> 9
A8: Compliance Rate | B8: =IFERROR(B4/(B4+B5),0) -> 0.85585586

Sheet MIS Summary
A1: MONTHLY MIS REPORT
A2: Monthly snapshot for management review. The reporting period can be changed in the source data.
A4: Month | B4: Total Activities | C4: Completed | D4: Pending | E4: In Progress | F4: TAT Met | G4: Checklist Complete
A5: 46235 | B5: =COUNTIFS('Activity Data'!$B:$B,">="&A5,'Activity Data'!$B:$B,"<"&EDATE(A5,1)) -> 60 | C5: =COUNTIFS('Activity Data'!$B:$B,">="&A5,'Activity Data'!$B:$B,"<"&EDATE(A5,1),'Activity Data'!$H:$H,"Completed") -> 40 | D5: =COUNTIFS('Activity Data'!$B:$B,">="&A5,'Activity Data'!$B:$B,"<"&EDATE(A5,1),'Activity Data'!$H:$H,"Pending") -> 3 | E5: =COUNTIFS('Activity Data'!$B:$B,">="&A5,'Activity Data'!$B:$B,"<"&EDATE(A5,1),'Activity Data'!$H:$H,"In Progress") -> 14 | F5: =COUNTIFS('Activity Data'!$B:$B,">="&A5,'Activity Data'!$B:$B,"<"&EDATE(A5,1),'Activity Data'!$J:$J,"Yes") -> 25 | G5: =COUNTIFS('Activity Data'!$B:$B,">="&A5,'Activity Data'!$B:$B,"<"&EDATE(A5,1),'Activity Data'!$I:$I,"Yes") -> 47
A6: 46266 | B6: =COUNTIFS('Activity Data'!$B:$B,">="&A6,'Activity Data'!$B:$B,"<"&EDATE(A6,1)) -> 60 | C6: =COUNTIFS('Activity Data'!$B:$B,">="&A6,'Activity Data'!$B:$B,"<"&EDATE(A6,1),'Activity Data'!$H:$H,"Completed") -> 40 | D6: =COUNTIFS('Activity Data'!$B:$B,">="&A6,'Activity Data'!$B:$B,"<"&EDATE(A6,1),'Activity Data'!$H:$H,"Pending") -> 4 | E6: =COUNTIFS('Activity Data'!$B:$B,">="&A6,'Activity Data'!$B:$B,"<"&EDATE(A6,1),'Activity Data'!$H:$H,"In Progress") -> 10 | F6: =COUNTIFS('Activity Data'!$B:$B,">="&A6,'Activity Data'!$B:$B,"<"&EDATE(A6,1),'Activity Data'!$J:$J,"Yes") -> 31 | G6: =COUNTIFS('Activity Data'!$B:$B,">="&A6,'Activity Data'!$B:$B,"<"&EDATE(A6,1),'Activity Data'!$I:$I,"Yes") -> 48
A7: 46296 | B7: =COUNTIFS('Activity Data'!$B:$B,">="&A7,'Activity Data'!$B:$B,"<"&EDATE(A7,1)) -> 0 | C7: =COUNTIFS('Activity Data'!$B:$B,">="&A7,'Activity Data'!$B:$B,"<"&EDATE(A7,1),'Activity Data'!$H:$H,"Completed") -> 0 | D7: =COUNTIFS('Activity Data'!$B:$B,">="&A7,'Activity Data'!$B:$B,"<"&EDATE(A7,1),'Activity Data'!$H:$H,"Pending") -> 0 | E7: =COUNTIFS('Activity Data'!$B:$B,">="&A7,'Activity Data'!$B:$B,"<"&EDATE(A7,1),'Activity Data'!$H:$H,"In Progress") -> 0 | F7: =COUNTIFS('Activity Data'!$B:$B,">="&A7,'Activity Data'!$B:$B,"<"&EDATE(A7,1),'Activity Data'!$J:$J,"Yes") -> 0 | G7: =COUNTIFS('Activity Data'!$B:$B,">="&A7,'Activity Data'!$B:$B,"<"&EDATE(A7,1),'Activity Data'!$I:$I,"Yes") -> 0

Sheet Lookup Practice
A1: LOOKUP FORMULA PRACTICE
A3: Enter an Activity ID in B3 (example: ACT-001) | B3: ACT-001
A5: Field | B5: XLOOKUP (Excel 365) | C5: VLOOKUP
A6: Date | B6: =_xludf.XLOOKUP($B$3,'Activity Data'!$A:$A,'Activity Data'!$B:$B,"Not found") -> #NAME? | C6: =IFERROR(VLOOKUP($B$3,'Activity Data'!$A:$J,2,FALSE),"Not found") -> 46282
A7: Region | B7: =_xludf.XLOOKUP($B$3,'Activity Data'!$A:$A,'Activity Data'!$C:$C,"Not found") -> #NAME? | C7: =IFERROR(VLOOKUP($B$3,'Activity Data'!$A:$J,3,FALSE),"Not found") -> North
A8: Assigned To | B8: =_xludf.XLOOKUP($B$3,'Activity Data'!$A:$A,'Activity Data'!$E:$E,"Not found") -> #NAME? | C8: =IFERROR(VLOOKUP($B$3,'Activity Data'!$A:$J,5,FALSE),"Not found") -> Meera
A9: Status | B9: =_xludf.XLOOKUP($B$3,'Activity Data'!$A:$A,'Activity Data'!$H:$H,"Not found") -> #NAME? | C9: =IFERROR(VLOOKUP($B$3,'Activity Data'!$A:$J,8,FALSE),"Not found") -> Cancelled
A10: TAT Met | B10: =_xludf.XLOOKUP($B$3,'Activity Data'!$A:$A,'Activity Data'!$J:$J,"Not found") -> #NAME? | C10: =IFERROR(VLOOKUP($B$3,'Activity Data'!$A:$J,10,FALSE),"Not found") -> N/A
A13: Tip | B13: If XLOOKUP is unavailable in your Excel version, use the VLOOKUP result.
